<?xml version="1.0" ?><!-- =================================================================================== --><!-- |    This document was autogenerated by xacro from /home/mouafak/ros2_ppp_ws/install/ppp_bot/share/ppp_bot/description/robot.urdf.xacro | --><!-- |    EDITING THIS FILE BY HAND IS NOT RECOMMENDED                                 | --><!-- =================================================================================== --><robot name="robot"><!-- Specify some standard inertial calculations https://en.wikipedia.org/wiki/List_of_moments_of_inertia --><!-- These make use of xacro's mathematical functionality --><material name="white"><color rgba="1 1 1 1"/></material><material name="orange"><color rgba="1 0.3 0.1 1"/></material><material name="blue"><color rgba="0.2 0.2 1 1"/></material><material name="red"><color rgba="1 0 0 1"/></material><material name="black"><color rgba="0 0 0 1"/></material><!-- BASE LINK --><link name="base_link">
    </link><!-- CHASSIS LINK --><joint name="chassis_joint" type="fixed"><parent link="base_link"/><child link="chassis"/><origin xyz="-0.1 0 0"/></joint><link name="chassis"><visual><origin xyz="0.15 0 0.075"/><geometry><box size="0.3 0.3 0.15"/></geometry><material name="white"/></visual><collision><origin xyz="0.15 0 0.075"/><geometry><box size="0.3 0.3 0.15"/></geometry></collision><inertial><origin rpy="0 0 0" xyz="0.15 0 0.075"/><mass value="0.5"/><inertia ixx="0.004687499999999999" ixy="0.0" ixz="0.0" iyy="0.004687499999999999" iyz="0.0" izz="0.0075"/></inertial></link><!-- LEFT WHEEL LINK --><joint name="left_wheel_joint" type="continuous"><parent link="base_link"/><child link="left_wheel"/><origin rpy="-1.5707963267948966 0 0" xyz="0 0.175 0"/><axis xyz="0 0 1"/></joint><link name="left_wheel"><visual><geometry><cylinder length="0.04" radius="0.05"/></geometry><material name="blue"/></visual><collision><geometry><cylinder length="0.04" radius="0.05"/></geometry></collision><inertial><origin rpy="0 0 0" xyz="0 0 0"/><mass value="0.1"/><inertia ixx="7.583333333333335e-05" ixy="0.0" ixz="0.0" iyy="7.583333333333335e-05" iyz="0.0" izz="0.00012500000000000003"/></inertial></link><!-- RIGHT WHEEL LINK --><joint name="right_wheel_joint" type="continuous"><parent link="base_link"/><child link="right_wheel"/><origin rpy="1.5707963267948966 0 0" xyz="0 -0.175 0"/><axis xyz="0 0 -1"/></joint><link name="right_wheel"><visual><geometry><cylinder length="0.04" radius="0.05"/></geometry><material name="blue"/></visual><collision><geometry><cylinder length="0.04" radius="0.05"/></geometry></collision><inertial><origin rpy="0 0 0" xyz="0 0 0"/><mass value="0.1"/><inertia ixx="7.583333333333335e-05" ixy="0.0" ixz="0.0" iyy="7.583333333333335e-05" iyz="0.0" izz="0.00012500000000000003"/></inertial></link><!-- CASTER WHEEL LINK --><joint name="caster_wheel_joint" type="fixed"><parent link="chassis"/><child link="caster_wheel"/><origin xyz="0.24 0 0"/></joint><link name="caster_wheel"><visual><geometry><sphere radius="0.05"/></geometry><material name="black"/></visual><collision><geometry><sphere radius="0.05"/></geometry></collision><inertial><origin rpy="0 0 0" xyz="0 0 0"/><mass value="0.1"/><inertia ixx="0.00010000000000000005" ixy="0.0" ixz="0.0" iyy="0.00010000000000000005" iyz="0.0" izz="0.00010000000000000005"/></inertial></link><gazebo reference="caster_wheel"><mu1 value="0.001"/><mu2 value="0.001"/></gazebo><gazebo><plugin filename="libignition-gazebo-diff-drive-system.so" name="ignition::gazebo::systems::DiffDrive"><left_joint>left_wheel_joint</left_joint><right_joint>right_wheel_joint</right_joint><wheel_separation>1.2</wheel_separation><wheel_radius>0.4</wheel_radius><odom_publish_frequency>1</odom_publish_frequency><topic>cmd_vel</topic></plugin></gazebo><joint name="lidar_joint" type="fixed"><parent link="chassis"/><child link="lidar_frame"/><origin rpy="0 0 0" xyz="0.1 0 0.19"/></joint><link name="lidar_frame"><visual><geometry><cylinder length="0.04" radius="0.05"/></geometry><material name="red"/></visual><collision><geometry><cylinder length="0.04" radius="0.05"/></geometry></collision><inertial><origin rpy="0 0 0" xyz="0 0 0"/><mass value="0.1"/><inertia ixx="7.583333333333335e-05" ixy="0.0" ixz="0.0" iyy="7.583333333333335e-05" iyz="0.0" izz="0.00012500000000000003"/></inertial></link><gazebo reference="lidar_frame"><sensor name="gpu_lidar" type="gpu_lidar"><topic>lidar</topic><update_rate>10</update_rate><lidar><scan><horizontal><samples>640</samples><resolution>1</resolution><min_angle>-1.396263</min_angle><max_angle>1.396263</max_angle></horizontal><vertical><samples>1</samples><resolution>1</resolution><min_angle>0.0</min_angle><max_angle>0.0</max_angle></vertical></scan><range><min>0.08</min><max>10.0</max><resolution>0.01</resolution></range></lidar><visualize>true</visualize></sensor></gazebo><joint name="camera_joint" type="fixed"><parent link="chassis"/><child link="camera_link"/><origin rpy="0 0 0" xyz="0.305 0 0.08"/></joint><link name="camera_link"><visual><geometry><box size="0.010 0.03 0.03"/></geometry><material name="red"/></visual></link><joint name="camera_optical_joint" type="fixed"><parent link="camera_link"/><child link="camera_link_optical"/><origin rpy="-1.5707963267948966 0 -1.5707963267948966" xyz="0 0 0"/></joint><link name="camera_link_optical"/><gazebo reference="camera_link"><material>Gazebo/Red</material><sensor name="camera" type="camera"><pose> 0 0 0 0 0 0 </pose><visualize>true</visualize><update_rate>10</update_rate><camera><horizontal_fov>1.089</horizontal_fov><image><format>R8G8B8</format><width>640</width><height>480</height></image><clip><near>0.05</near><far>8.0</far></clip></camera></sensor></gazebo><joint name="depth_camera_joint" type="fixed"><parent link="chassis"/><child link="depth_camera_link"/><origin rpy="0 0 0" xyz="0.305 0 0.08"/></joint><link name="depth_camera_link"><visual><geometry><box size="0.010 0.03 0.03"/></geometry><material name="red"/></visual></link><joint name="depth_camera_optical_joint" type="fixed"><parent link="depth_camera_link"/><child link="depth_camera_link_optical"/><origin rpy="-1.5707963267948966 0 -1.5707963267948966" xyz="0 0 0"/></joint><link name="depth_camera_link_optical"/><gazebo reference="depth_camera_link"><sensor name="depth_camera" type="depth"><pose> 0 0 0 0 0 0 </pose><visualize>true</visualize><update_rate>10</update_rate><camera><horizontal_fov>1.089</horizontal_fov><image><format>B8G8R8</format><width>640</width><height>480</height></image><clip><near>0.05</near><far>8.0</far></clip></camera></sensor></gazebo></robot>